[ERROR]   [2018-10-25 Thu, AM 11:31:20,370] log_helper.py [line:404]: type.__new__() takes exactly 3 arguments (0 given)
[ERROR]   [2018-10-25 Thu, AM 11:31:20,373] log.py [line:228]: Internal Server Error: /erp/salesInfoPre/save/
[ERROR]   [2018-10-25 Thu, PM 14:18:58,114] log_helper.py [line:404]: 'NoneType' object has no attribute 'request'
[ERROR]   [2018-10-25 Thu, PM 14:18:58,117] log.py [line:228]: Internal Server Error: /erp/salesInfoPre/save/
[ERROR]   [2018-10-25 Thu, PM 14:19:58,869] log_helper.py [line:404]: 'NoneType' object has no attribute 'request'
[ERROR]   [2018-10-25 Thu, PM 14:19:58,872] log.py [line:228]: Internal Server Error: /erp/salesInfoPre/save/
[ERROR]   [2018-10-25 Thu, PM 14:21:56,697] log_helper.py [line:404]: type.__new__() takes exactly 3 arguments (1 given)
[ERROR]   [2018-10-25 Thu, PM 14:21:56,699] log.py [line:228]: Internal Server Error: /erp/salesInfoPre/save/
[ERROR]   [2018-10-25 Thu, PM 14:22:38,233] log_helper.py [line:404]: type.__new__(X): X is not a type object (Request)
[ERROR]   [2018-10-25 Thu, PM 14:22:38,236] log.py [line:228]: Internal Server Error: /erp/salesInfoPre/save/
[ERROR]   [2018-10-25 Thu, PM 14:23:35,180] log_helper.py [line:404]: type.__new__() takes exactly 3 arguments (0 given)
[ERROR]   [2018-10-25 Thu, PM 14:23:35,183] log.py [line:228]: Internal Server Error: /erp/salesInfoPre/save/
[ERROR]   [2018-10-25 Thu, PM 14:44:07,413] log_helper.py [line:404]: 'Request' object has no attribute 'session_manager'
[ERROR]   [2018-10-25 Thu, PM 14:44:07,417] log.py [line:228]: Internal Server Error: /erp/contactUnitApi/
[ERROR]   [2018-10-25 Thu, PM 14:46:06,971] log_helper.py [line:404]: 'Request' object has no attribute 'session_manager'
[ERROR]   [2018-10-25 Thu, PM 14:46:06,975] log.py [line:228]: Internal Server Error: /erp/contactUnitApi/
[ERROR]   [2018-10-25 Thu, PM 14:54:07,646] log_helper.py [line:404]: 'Request' object has no attribute 'session_manager'
[ERROR]   [2018-10-25 Thu, PM 14:54:07,650] log.py [line:228]: Internal Server Error: /erp/contactUnitApi/
[ERROR]   [2018-10-25 Thu, PM 14:57:30,724] log_helper.py [line:404]: 'Request' object has no attribute 'session_manager'
[ERROR]   [2018-10-25 Thu, PM 14:57:30,728] log.py [line:228]: Internal Server Error: /erp/contactUnitApi/
[ERROR]   [2018-10-25 Thu, PM 15:05:50,850] log_helper.py [line:404]: 'Request' object has no attribute 'session_manager'
[ERROR]   [2018-10-25 Thu, PM 15:05:50,852] log.py [line:228]: Internal Server Error: /erp/contactUnitApi/
[ERROR]   [2018-10-25 Thu, PM 15:08:09,097] log_helper.py [line:404]: __call__() takes 1 positional argument but 2 were given
[ERROR]   [2018-10-25 Thu, PM 15:08:09,100] log.py [line:228]: Internal Server Error: /erp/salesInfoPre/save/
[ERROR]   [2018-10-25 Thu, PM 15:12:26,535] log_helper.py [line:404]: name 'arg_list' is not defined
[ERROR]   [2018-10-25 Thu, PM 15:12:26,536] log.py [line:228]: Internal Server Error: /erp/salesInfoPre/save/
[ERROR]   [2018-10-25 Thu, PM 17:25:44,787] log_helper.py [line:404]: __init__() got an unexpected keyword argument 'bb'
[ERROR]   [2018-10-25 Thu, PM 17:25:47,140] log.py [line:228]: Internal Server Error: /erp/salesInfoPre/getById/
[ERROR]   [2018-10-25 Thu, PM 17:26:33,571] log_helper.py [line:404]: __init__() got an unexpected keyword argument 'bb'
[ERROR]   [2018-10-25 Thu, PM 17:26:40,702] log.py [line:228]: Internal Server Error: /erp/salesInfoPre/getById/
[ERROR]   [2018-10-25 Thu, PM 17:29:49,323] log_helper.py [line:404]: __init__() got an unexpected keyword argument 'bb'
[ERROR]   [2018-10-25 Thu, PM 17:29:49,324] log.py [line:228]: Internal Server Error: /erp/salesInfoPre/getById/
[ERROR]   [2018-10-25 Thu, PM 17:32:49,037] log_helper.py [line:404]: HttpResponseWorkflow() got an unexpected keyword argument 'bb'
[ERROR]   [2018-10-25 Thu, PM 17:32:49,039] log.py [line:228]: Internal Server Error: /erp/salesInfoPre/getById/
